<!DOCTYPE html>
<html lang="en">
  <head>
    <meta charset="UTF-8" />
    <meta name="viewport" content="width=device-width, initial-scale=1.0" />
    <title>Promise</title>
    <script>
      //javascript is a synchronous programing language .However callback fn enable to transform into asynchronous.

      //understand basics

      console.log("Hello World");
      //we want to console after 5sec
      setTimeout(() => {
        console.log("Hi Manohar");
      }, 5000);

      console.log("Hi Babban");

      //let us understand with e commerce example

      const cart = ["phone", "bag", "shoes", "pants"];
      //first create a order after that callback fn proceed to payment
      api.creatOrder(cart, function () {
        api.proceedToPayment();
      });

      //after payment we want to show order summery so we pass callback function inside
      api.creatOrder(cart, function () {
        api.proceedToPayment(() => {
          api.showOrderSummary();
        });
      });
      //we observed  issue  that callback fn inside callback known as callback hell
      // one more issue with createOrder Inversion of Control

      //Promise  in JavaScript help to getout of Callback hell and then resolve Inversion of Control

      //Promise has three methods available to it ( then , catch , & finally )
      function getUsers() {
        return new Promise((resolve, reject) => {
          setTimeout(() => {
            resolve([
              { username: "manohar", email: "manohar@test.com" },
              { username: "babban", email: "babban@test.com" },
              { username: "Manish", email: "manish@test.com" },
              { username: "Kishor", email: "kishor@test.com" },
            ]);
          }, 1000);
        });
      }

      function onFulfilled(users) {
        console.log(users);
      }

      const promise1 = getUsers();
      promise1.then(onFulfilled);
      //then() method accepts two callback functions: onFulfilled and onRejected.
      //The then() method calls the onFulfilled() with a value,

      //if the promise is fulfilled or the onRejected() with an error if the promise is rejected.

      //To make the code more concise, you can use an arrow function
      function getUsers() {
        return new Promise((resolve, reject) => {
          setTimeout(() => {
            resolve([
              { username: "manohar", email: "manohar@test.com" },
              { username: "babban", email: "babban@test.com" },
              { username: "Manish", email: "manish@test.com" },
              { username: "Kishor", email: "kishor@test.com" },
            ]);
          }, 1000);
        });
      }

      const promise = getUsers();

      promise.then((users) => {
        console.log(users);
      });

      //understand catch method
      let success = true;

      function getUsers() {
        return new Promise((resolve, reject) => {
          setTimeout(() => {
            if (success) {
              resolve([
                { username: "manohar", email: "manohar@test.com" },
                { username: "babban", email: "babban@test.com" },
                { username: "Manish", email: "manish@test.com" },
                { username: "Kishor", email: "kishor@test.com" },
              ]);
            } else {
              reject("Failed to the user list");
            }
          }, 1000);
        });
      }

      function onFulfilled(users) {
        console.log(users);
      }
      function onRejected(error) {
        console.log(error);
      }

      const promise2 = getUsers();
      promise.then(onFulfilled, onRejected);
      //Internally, the catch() method invokes the then(undefined, onRejected) method.
      //The following example changes the success flag to false to simulate the error scenario:
      let success2 = false;

      function getUsers() {
        return new Promise((resolve, reject) => {
          setTimeout(() => {
            if (success2) {
              resolve([
                { username: "manohar", email: "manohar@test.com" },
                { username: "babban", email: "babban@test.com" },
                { username: "Manish", email: "manish@test.com" },
                { username: "Kishor", email: "kishor@test.com" },
              ]);
            } else {
              reject("Failed to the user list");
            }
          }, 1000);
        });
      }

      const promise4 = getUsers();

      promise4.catch((error) => {
        console.log(error);
      });
    </script>
  </head>
  <body></body>
</html>
